Workbook

Sheet MALLAS
A1: Clave | B1: Nombre Asignatura | C1: Cr. | D1: SCT | E1: Pre-requisitos | F1: Semestre | G1: Homologaciones | H1: SeDicta? | I1: Se Dicta Homologable? | J1: Carrera | K1: curs | L1: max | M1: prob_aprob | N1: max 2 | O1: CÁTEDRA | P1: AYUDANTIA | Q1: TALLER | R1: LABORATORIO
A2: ICD1401 | B2: BIENESTAR,APRENDIZAJE UNIVERSITARIO | C2: 2 | D2: =C2*1.5 -> 3 | F2: 1 | G2: ICI1458 | H2: =if(IFERROR(VLOOKUP(A2,'Asignaturas2026-2'!B:B,1,False),"")<>"","SI",IF(I2<>"","HOM","")) -> #REF! | I2: =IFERROR(__xludf.DUMMYFUNCTION("if(or(L2=0),"""",IFERROR(TEXTJOIN("", "", TRUE, FILTER( TRIM(SPLIT(G2, "","")), MAP( TRIM(SPLIT(G2, "","")), LAMBDA(clave, COUNTIF('Asignaturas2026-2'!B:B, clave )>0 ) ) ) )))"),"#REF!") -> #REF! | J2: ICD | K2: =COUNTIF(ALUMNOS!D:D,"*"&A2&"*") -> #REF! | L2: =COUNTIF(ALUMNOS!E:E,"*"&A2&"*") -> #REF! | M2: 0.92 | N2: 50 | O2: 2 | P2: 0 | Q2: 0 | R2: 0
A3: ICD1341 | B3: FUNDAMENTOS DE ALGORITMOS | C3: 4 | D3: =C3*1.5 -> 6 | F3: 1 | G3: INF1211,INF1141,ICI1141,INF298,ICI1241 | H3: =if(IFERROR(VLOOKUP(A3,'Asignaturas2026-2'!B:B,1,False),"")<>"","SI",IF(I3<>"","HOM","")) -> #REF! | I3: =IFERROR(__xludf.DUMMYFUNCTION("if(or(L3=0),"""",IFERROR(TEXTJOIN("", "", TRUE, FILTER( TRIM(SPLIT(G3, "","")), MAP( TRIM(SPLIT(G3, "","")), LAMBDA(clave, COUNTIF('Asignaturas2026-2'!B:B, clave )>0 ) ) ) )))"),"#REF!") -> #REF! | J3: ICD | K3: =COUNTIF(ALUMNOS!D:D,"*"&A3&"*") -> #REF! | L3: =COUNTIF(ALUMNOS!E:E,"*"&A3&"*") -> #REF! | M3: 0.5 | N3: 27 | O3: 4 | P3: 2 | Q3: 0 | R3: 0
A4: ICD1140 | B4: INTRODUCCION A LA INGENIERIA EN CIENCIA DE DATOS | C4: 6 | D4: =C4*1.5 -> 9 | F4: 1 | G4: INF1212,FIN110 | H4: =if(IFERROR(VLOOKUP(A4,'Asignaturas2026-2'!B:B,1,False),"")<>"","SI",IF(I4<>"","HOM","")) -> #REF! | I4: =IFERROR(__xludf.DUMMYFUNCTION("if(or(L4=0),"""",IFERROR(TEXTJOIN("", "", TRUE, FILTER( TRIM(SPLIT(G4, "","")), MAP( TRIM(SPLIT(G4, "","")), LAMBDA(clave, COUNTIF('Asignaturas2026-2'!B:B, clave )>0 ) ) ) )))"),"#REF!") -> #REF! | J4: ICD | K4: =COUNTIF(ALUMNOS!D:D,"*"&A4&"*") -> #REF! | L4: =COUNTIF(ALUMNOS!E:E,"*"&A4&"*") -> #REF! | M4: 1 | N4: 50 | O4: 4 | P4: 2 | Q4: 0 | R4: 0
A5: MAT1001 | B5: FUNDAMENTOS DE MATEMATICAS PARA INGENIERIA | C5: 6 | D5: =C5*1.5 -> 9 | F5: 1 | G5: MAT1196,MAT1197 | H5: =if(IFERROR(VLOOKUP(A5,'Asignaturas2026-2'!B:B,1,False),"")<>"","SI",IF(I5<>"","HOM","")) -> #REF! | I5: =IFERROR(__xludf.DUMMYFUNCTION("if(or(L5=0),"""",IFERROR(TEXTJOIN("", "", TRUE, FILTER( TRIM(SPLIT(G5, "","")), MAP( TRIM(SPLIT(G5, "","")), LAMBDA(clave, COUNTIF('Asignaturas2026-2'!B:B, clave )>0 ) ) ) )))"),"#REF!") -> #REF! | J5: ICD | K5: =COUNTIF(ALUMNOS!D:D,"*"&A5&"*") -> #REF! | L5: =COUNTIF(ALUMNOS!E:E,"*"&A5&"*") -> #REF! | M5: 0.57 | N5: 50 | O5: 6 | P5: 0 | Q5: 4 | R5: 0
A6: FIN100-14 | B6: DESARROLLO INTEGRAL,COMUNICACION PARA INGENIERIA | C6: 3 | D6: =C6*1.5 -> 4.5 | F6: 2 | G6: FIN100-73,FIN100-15,FIN100-11,FIN100-16,FIN100-12,FIN100-296,FIN100-7,FIN100 | H6: =if(IFERROR(VLOOKUP(A6,'Asignaturas2026-2'!B:B,1,False),"")<>"","SI",IF(I6<>"","HOM","")) -> #REF! | I6: =IFERROR(__xludf.DUMMYFUNCTION("if(or(L6=0),"""",IFERROR(TEXTJOIN("", "", TRUE, FILTER( TRIM(SPLIT(G6, "","")), MAP( TRIM(SPLIT(G6, "","")), LAMBDA(clave, COUNTIF('Asignaturas2026-2'!B:B, clave )>0 ) ) ) )))"),"#REF!") -> #REF! | J6: ICD | K6: =COUNTIF(ALUMNOS!D:D,"*"&A6&"*") -> #REF! | L6: =COUNTIF(ALUMNOS!E:E,"*"&A6&"*") -> #REF! | M6: 1 | N6: 50 | O6: 2 | P6: 0 | Q6: 2 | R6: 0
A7: ICD1342 | B7: FUNDAMENTOS DE PROGRAMACION | C7: 4 | D7: =C7*1.5 -> 6 | E7: ICD1341 | F7: 2 | G7: INF1214,INF1142,ICI1142,ICI1242 | H7: =if(IFERROR(VLOOKUP(A7,'Asignaturas2026-2'!B:B,1,False),"")<>"","SI",IF(I7<>"","HOM","")) -> #REF! | I7: =IFERROR(__xludf.DUMMYFUNCTION("if(or(L7=0),"""",IFERROR(TEXTJOIN("", "", TRUE, FILTER( TRIM(SPLIT(G7, "","")), MAP( TRIM(SPLIT(G7, "","")), LAMBDA(clave, COUNTIF('Asignaturas2026-2'!B:B, clave )>0 ) ) ) )))"),"#REF!") -> #REF! | J7: ICD | K7: =COUNTIF(ALUMNOS!D:D,"*"&A7&"*") -> #REF! | L7: =COUNTIF(ALUMNOS!E:E,"*"&A7&"*") -> #REF! | M7: 0.31 | N7: 30 | O7: 4 | P7: 2 | Q7: 0 | R7: 0
A8: MAT1002 | B8: CALCULO DIFERENCIAL E INTEGRAL | C8: 6 | D8: =C8*1.5 -> 9 | E8: MAT1001 | F8: 2 | G8: MAT2178,MAT2188 | H8: =if(IFERROR(VLOOKUP(A8,'Asignaturas2026-2'!B:B,1,False),"")<>"","SI",IF(I8<>"","HOM","")) -> #REF! | I8: =IFERROR(__xludf.DUMMYFUNCTION("if(or(L8=0),"""",IFERROR(TEXTJOIN("", "", TRUE, FILTER( TRIM(SPLIT(G8, "","")), MAP( TRIM(SPLIT(G8, "","")), LAMBDA(clave, COUNTIF('Asignaturas2026-2'!B:B, clave )>0 ) ) ) )))"),"#REF!") -> #REF! | J8: ICD | K8: =COUNTIF(ALUMNOS!D:D,"*"&A8&"*") -> #REF! | L8: =COUNTIF(ALUMNOS!E:E,"*"&A8&"*") -> #REF! | M8: 0.25 | N8: 50 | O8: 6 | P8: 0 | Q8: 4 | R8: 0
A9: MAT1004 | B9: ALGEBRA LINEAL | C9: 4 | D9: =C9*1.5 -> 6 | E9: MAT1001 | F9: 2 | G9: MAT1169,MAT1167 | H9: =if(IFERROR(VLOOKUP(A9,'Asignaturas2026-2'!B:B,1,False),"")<>"","SI",IF(I9<>"","HOM","")) -> #REF! | I9: =IFERROR(__xludf.DUMMYFUNCTION("if(or(L9=0),"""",IFERROR(TEXTJOIN("", "", TRUE, FILTER( TRIM(SPLIT(G9, "","")), MAP( TRIM(SPLIT(G9, "","")), LAMBDA(clave, COUNTIF('Asignaturas2026-2'!B:B, clave )>0 ) ) ) )))"),"#REF!") -> #REF! | J9: ICD | K9: =COUNTIF(ALUMNOS!D:D,"*"&A9&"*") -> #REF! | L9: =COUNTIF(ALUMNOS!E:E,"*"&A9&"*") -> #REF! | M9: 0.25 | N9: 50 | O9: 4 | P9: 0 | Q9: 2 | R9: 0
A10: IER010 | B10: ANTROPOLOGIA CRISTIANA | C10: 2 | D10: =C10*1.5 -> 3 | F10: 3 | G10: ANTROPOLOGIA CRISTIANA | H10: =if(IFERROR(VLOOKUP(A10,'Asignaturas2026-2'!B:B,1,False),"")<>"","SI",IF(I10<>"","HOM","")) -> #REF! | I10: =IFERROR(__xludf.DUMMYFUNCTION("if(or(L10=0),"""",IFERROR(TEXTJOIN("", "", TRUE, FILTER( TRIM(SPLIT(G10, "","")), MAP( TRIM(SPLIT(G10, "","")), LAMBDA(clave, COUNTIF('Asignaturas2026-2'!B:B, clave )>0 ) ) ) )))"),"#REF!") -> #REF! | J10: ICD | K10: =COUNTIF(ALUMNOS!D:D,"*"&A10&"*") -> #REF! | L10: =COUNTIF(ALUMNOS!E:E,"*"&A10&"*") -> #REF! | M10: 1 | O10: 2 | P10: 0 | Q10: 0 | R10: 0
A11: ICD2243 | B11: INTRODUCCION AL ANALISIS DE DATOS | C11: 4 | D11: =C11*1.5 -> 6 | E11: ICD1140,MAT1004 | F11: 3 | H11: =if(IFERROR(VLOOKUP(A11,'Asignaturas2026-2'!B:B,1,False),"")<>"","SI",IF(I11<>"","HOM","")) -> #REF! | I11: =IFERROR(__xludf.DUMMYFUNCTION("if(or(L11=0),"""",IFERROR(TEXTJOIN("", "", TRUE, FILTER( TRIM(SPLIT(G11, "","")), MAP( TRIM(SPLIT(G11, "","")), LAMBDA(clave, COUNTIF('Asignaturas2026-2'!B:B, clave )>0 ) ) ) )))"),"#REF!") -> #REF! | J11: ICD | K11: =COUNTIF(ALUMNOS!D:D,"*"&A11&"*") -> #REF! | L11: =COUNTIF(ALUMNOS!E:E,"*"&A11&"*") -> #REF! | M11: 0.96 | N11: 50 | O11: 4 | P11: 2 | Q11: 0 | R11: 0
A12: ICD2344 | B12: ESTRUCTURA DE DATOS | C12: 4 | D12: =C12*1.5 -> 6 | E12: ICD1342 | F12: 3 | G12: INF2223,INF2240,ICI2240 | H12: =if(IFERROR(VLOOKUP(A12,'Asignaturas2026-2'!B:B,1,False),"")<>"","SI",IF(I12<>"","HOM","")) -> #REF! | I12: =IFERROR(__xludf.DUMMYFUNCTION("if(or(L12=0),"""",IFERROR(TEXTJOIN("", "", TRUE, FILTER( TRIM(SPLIT(G12, "","")), MAP( TRIM(SPLIT(G12, "","")), LAMBDA(clave, COUNTIF('Asignaturas2026-2'!B:B, clave )>0 ) ) ) )))"),"#REF!") -> #REF! | J12: ICD | K12: =COUNTIF(ALUMNOS!D:D,"*"&A12&"*") -> #REF! | L12: =COUNTIF(ALUMNOS!E:E,"*"&A12&"*") -> #REF! | M12: 0.93 | N12: 50 | O12: 4 | P12: 2 | Q12: 0 | R12: 0
A13: FIS1002 | B13: FISICA PARA INGENIERIA | C13: 5 | D13: =C13*1.5 -> 7.5 | E13: MAT1001 | F13: 3 | G13: FIS2109,FIS2115 | H13: =if(IFERROR(VLOOKUP(A13,'Asignaturas2026-2'!B:B,1,False),"")<>"","SI",IF(I13<>"","HOM","")) -> #REF! | I13: =IFERROR(__xludf.DUMMYFUNCTION("if(or(L13=0),"""",IFERROR(TEXTJOIN("", "", TRUE, FILTER( TRIM(SPLIT(G13, "","")), MAP( TRIM(SPLIT(G13, "","")), LAMBDA(clave, COUNTIF('Asignaturas2026-2'!B:B, clave )>0 ) ) ) )))"),"#REF!") -> #REF! | J13: ICD | K13: =COUNTIF(ALUMNOS!D:D,"*"&A13&"*") -> #REF! | L13: =COUNTIF(ALUMNOS!E:E,"*"&A13&"*") -> #REF! | M13: 1 | N13: 50 | O13: 6 | P13: 0 | Q13: 2 | R13: 0
A14: MAT1003 | B14: CALCULO EN VARIAS VARIABLES | C14: 4 | D14: =C14*1.5 -> 6 | E14: MAT1002 | F14: 3 | G14: MAT2198 | H14: =if(IFERROR(VLOOKUP(A14,'Asignaturas2026-2'!B:B,1,False),"")<>"","SI",IF(I14<>"","HOM","")) -> #REF! | I14: =IFERROR(__xludf.DUMMYFUNCTION("if(or(L14=0),"""",IFERROR(TEXTJOIN("", "", TRUE, FILTER( TRIM(SPLIT(G14, "","")), MAP( TRIM(SPLIT(G14, "","")), LAMBDA(clave, COUNTIF('Asignaturas2026-2'!B:B, clave )>0 ) ) ) )))"),"#REF!") -> #REF! | J14: ICD | K14: =COUNTIF(ALUMNOS!D:D,"*"&A14&"*") -> #REF! | L14: =COUNTIF(ALUMNOS!E:E,"*"&A14&"*") -> #REF! | M14: 0.8 | N14: 50 | O14: 4 | P14: 0 | Q14: 2 | R14: 0
A15: ING9001 | B15: INGLES 1 | C15: 2 | D15: =C15*1.5 -> 3 | F15: 4 | H15: =if(IFERROR(VLOOKUP(A15,'Asignaturas2026-2'!B:B,1,False),"")<>"","SI",IF(I15<>"","HOM","")) -> #REF! | I15: =IFERROR(__xludf.DUMMYFUNCTION("if(or(L15=0),"""",IFERROR(TEXTJOIN("", "", TRUE, FILTER( TRIM(SPLIT(G15, "","")), MAP( TRIM(SPLIT(G15, "","")), LAMBDA(clave, COUNTIF('Asignaturas2026-2'!B:B, clave )>0 ) ) ) )))"),"#REF!") -> #REF! | J15: ICD | K15: =COUNTIF(ALUMNOS!D:D,"*"&A15&"*") -> #REF! | L15: =COUNTIF(ALUMNOS!E:E,"*"&A15&"*") -> #REF! | M15: 1 | N15: 25 | O15: 4 | P15: 0 | Q15: 2 | R15: 0
A16: FIS2120 | B16: FISICA ELECTROMAGNETISMO | C16: 3 | D16: =C16*1.5 -> 4.5 | E16: FIS1002 | F16: 4 | H16: =if(IFERROR(VLOOKUP(A16,'Asignaturas2026-2'!B:B,1,False),"")<>"","SI",IF(I16<>"","HOM","")) -> #REF! | I16: =IFERROR(__xludf.DUMMYFUNCTION("if(or(L16=0),"""",IFERROR(TEXTJOIN("", "", TRUE, FILTER( TRIM(SPLIT(G16, "","")), MAP( TRIM(SPLIT(G16, "","")), LAMBDA(clave, COUNTIF('Asignaturas2026-2'!B:B, clave )>0 ) ) ) )))"),"#REF!") -> #REF! | J16: ICD | K16: =COUNTIF(ALUMNOS!D:D,"*"&A16&"*") -> #REF! | L16: =COUNTIF(ALUMNOS!E:E,"*"&A16&"*") -> #REF! | M16: 1 | N16: 50 | O16: 2 | P16: 2 | Q16: 2 | R16: 0
A17: ICD2145 | B17: CIENCIA,TECNOLOGIA | C17: 3 | D17: =C17*1.5 -> 4.5 | E17: ICD1342 | F17: 4 | G17: ICI3150 | H17: =if(IFERROR(VLOOKUP(A17,'Asignaturas2026-2'!B:B,1,False),"")<>"","SI",IF(I17<>"","HOM","")) -> #REF! | I17: =IFERROR(__xludf.DUMMYFUNCTION("if(or(L17=0),"""",IFERROR(TEXTJOIN("", "", TRUE, FILTER( TRIM(SPLIT(G17, "","")), MAP( TRIM(SPLIT(G17, "","")), LAMBDA(clave, COUNTIF('Asignaturas2026-2'!B:B, clave )>0 ) ) ) )))"),"#REF!") -> #REF! | J17: ICD | K17: =COUNTIF(ALUMNOS!D:D,"*"&A17&"*") -> #REF! | L17: =COUNTIF(ALUMNOS!E:E,"*"&A17&"*") -> #REF! | M17: 1 | N17: 50 | O17: 4 | P17: 2 | Q17: 0 | R17: 0
A18: ICD2346 | B18: PARADIGMAS DE PROGRAMACION | C18: 3 | D18: =C18*1.5 -> 4.5 | E18: ICD1342 | F18: 4 | H18: =if(IFERROR(VLOOKUP(A18,'Asignaturas2026-2'!B:B,1,False),"")<>"","SI",IF(I18<>"","HOM","")) -> #REF! | I18: =IFERROR(__xludf.DUMMYFUNCTION("if(or(L18=0),"""",IFERROR(TEXTJOIN("", "", TRUE, FILTER( TRIM(SPLIT(G18, "","")), MAP( TRIM(SPLIT(G18, "","")), LAMBDA(clave, COUNTIF('Asignaturas2026-2'!B:B, clave )>0 ) ) ) )))"),"#REF!") -> #REF! | J18: ICD | K18: =COUNTIF(ALUMNOS!D:D,"*"&A18&"*") -> #REF! | L18: =COUNTIF(ALUMNOS!E:E,"*"&A18&"*") -> #REF! | M18: 1 | N18: 50 | O18: 4 | P18: 0 | Q18: 0 | R18: 0
A19: MAT3105 | B19: ECUACIONES DIFERENCIALES | C19: 3 | D19: =C19*1.5 -> 4.5 | E19: MAT1003 | F19: 4 | H19: =if(IFERROR(VLOOKUP(A19,'Asignaturas2026-2'!B:B,1,False),"")<>"","SI",IF(I19<>"","HOM","")) -> #REF! | I19: =IFERROR(__xludf.DUMMYFUNCTION("if(or(L19=0),"""",IFERROR(TEXTJOIN("", "", TRUE, FILTER( TRIM(SPLIT(G19, "","")), MAP( TRIM(SPLIT(G19, "","")), LAMBDA(clave, COUNTIF('Asignaturas2026-2'!B:B, clave )>0 ) ) ) )))"),"#REF!") -> #REF! | J19: ICD | K19: =COUNTIF(ALUMNOS!D:D,"*"&A19&"*") -> #REF! | L19: =COUNTIF(ALUMNOS!E:E,"*"&A19&"*") -> #REF! | M19: 1 | N19: 50 | O19: 4 | P19: 2 | Q19: 0 | R19: 0
A20: ICD2347 | B20: ANALISIS,DISEÑO DE ALGORITMOS | C20: 4 | D20: =C20*1.5 -> 6 | E20: ICD2344 | F20: 4 | G20: ICI2242 | H20: =if(IFERROR(VLOOKUP(A20,'Asignaturas2026-2'!B:B,1,False),"")<>"","SI",IF(I20<>"","HOM","")) -> #REF! | I20: =IFERROR(__xludf.DUMMYFUNCTION("if(or(L20=0),"""",IFERROR(TEXTJOIN("", "", TRUE, FILTER( TRIM(SPLIT(G20, "","")), MAP( TRIM(SPLIT(G20, "","")), LAMBDA(clave, COUNTIF('Asignaturas2026-2'!B:B, clave )>0 ) ) ) )))"),"#REF!") -> #REF! | J20: ICD | K20: =COUNTIF(ALUMNOS!D:D,"*"&A20&"*") -> #REF! | L20: =COUNTIF(ALUMNOS!E:E,"*"&A20&"*") -> #REF! | M20: 1 | N20: 50 | O20: 4 | P20: 2 | Q20: 0 | R20: 0
A21: ING9002 | B21: INGLES 2 | C21: 2 | D21: =C21*1.5 -> 3 | E21: ING9001 | F21: 5 | H21: =if(IFERROR(VLOOKUP(A21,'Asignaturas2026-2'!B:B,1,False),"")<>"","SI",IF(I21<>"","HOM","")) -> #REF! | I21: =IFERROR(__xludf.DUMMYFUNCTION("if(or(L21=0),"""",IFERROR(TEXTJOIN("", "", TRUE, FILTER( TRIM(SPLIT(G21, "","")), MAP( TRIM(SPLIT(G21, "","")), LAMBDA(clave, COUNTIF('Asignaturas2026-2'!B:B, clave )>0 ) ) ) )))"),"#REF!") -> #REF! | J21: ICD | K21: =COUNTIF(ALUMNOS!D:D,"*"&A21&"*") -> #REF! | L21: =COUNTIF(ALUMNOS!E:E,"*"&A21&"*") -> #REF! | M21: 1 | N21: 25 | O21: 4 | P21: 0 | Q21: 2 | R21: 0
A22: FIS3149 | B22: FISICA MODERNA | C22: 3 | D22: =C22*1.5 -> 4.5 | E22: FIS1002 | F22: 5 | H22: =if(IFERROR(VLOOKUP(A22,'Asignaturas2026-2'!B:B,1,False),"")<>"","SI",IF(I22<>"","HOM","")) -> #REF! | I22: =IFERROR(__xludf.DUMMYFUNCTION("if(or(L22=0),"""",IFERROR(TEXTJOIN("", "", TRUE, FILTER( TRIM(SPLIT(G22, "","")), MAP( TRIM(SPLIT(G22, "","")), LAMBDA(clave, COUNTIF('Asignaturas2026-2'!B:B, clave )>0 ) ) ) )))"),"#REF!") -> #REF! | J22: ICD | K22: =COUNTIF(ALUMNOS!D:D,"*"&A22&"*") -> #REF! | L22: =COUNTIF(ALUMNOS!E:E,"*"&A22&"*") -> #REF! | M22: 1 | N22: 50 | O22: 2 | P22: 2 | Q22: 2 | R22: 0
A23: ICD3149 | B23: TEORIA DE SISTEMAS | C23: 3 | D23: =C23*1.5 -> 4.5 | F23: 5 | G23: ICI2140 | H23: =if(IFERROR(VLOOKUP(A23,'Asignaturas2026-2'!B:B,1,False),"")<>"","SI",IF(I23<>"","HOM","")) -> #REF! | I23: =IFERROR(__xludf.DUMMYFUNCTION("if(or(L23=0),"""",IFERROR(TEXTJOIN("", "", TRUE, FILTER( TRIM(SPLIT(G23, "","")), MAP( TRIM(SPLIT(G23, "","")), LAMBDA(clave, COUNTIF('Asignaturas2026-2'!B:B, clave )>0 ) ) ) )))"),"#REF!") -> #REF! | J23: ICD | K23: =COUNTIF(ALUMNOS!D:D,"*"&A23&"*") -> #REF! | L23: =COUNTIF(ALUMNOS!E:E,"*"&A23&"*") -> #REF! | M23: 0.94 | N23: 50 | O23: 4 | P23: 0 | Q23: 0 | R23: 0
A24: ICD3148 | B24: ESTADISTICA COMPUTACIONAL | C24: 4 | D24: =C24*1.5 -> 6 | E24: MAT1003 | F24: 5 | G24: ICI3170 | H24: =if(IFERROR(VLOOKUP(A24,'Asignaturas2026-2'!B:B,1,False),"")<>"","SI",IF(I24<>"","HOM","")) -> #REF! | I24: =IFERROR(__xludf.DUMMYFUNCTION("if(or(L24=0),"""",IFERROR(TEXTJOIN("", "", TRUE, FILTER( TRIM(SPLIT(G24, "","")), MAP( TRIM(SPLIT(G24, "","")), LAMBDA(clave, COUNTIF('Asignaturas2026-2'!B:B, clave )>0 ) ) ) )))"),"#REF!") -> #REF! | J24: ICD | K24: =COUNTIF(ALUMNOS!D:D,"*"&A24&"*") -> #REF! | L24: =COUNTIF(ALUMNOS!E:E,"*"&A24&"*") -> #REF! | M24: 0.9 | N24: 50 | O24: 4 | P24: 2 | Q24: 0 | R24: 0
A25: ICD3350 | B25: BASE DE DATOS | C25: 4 | D25: =C25*1.5 -> 6 | E25: ICD2344 | F25: 5 | G25: INF2235,INF2243,ICI3243,ICI3240 | H25: =if(IFERROR(VLOOKUP(A25,'Asignaturas2026-2'!B:B,1,False),"")<>"","SI",IF(I25<>"","HOM","")) -> #REF! | I25: =IFERROR(__xludf.DUMMYFUNCTION("if(or(L25=0),"""",IFERROR(TEXTJOIN("", "", TRUE, FILTER( TRIM(SPLIT(G25, "","")), MAP( TRIM(SPLIT(G25, "","")), LAMBDA(clave, COUNTIF('Asignaturas2026-2'!B:B, clave )>0 ) ) ) )))"),"#REF!") -> #REF! | J25: ICD | K25: =COUNTIF(ALUMNOS!D:D,"*"&A25&"*") -> #REF! | L25: =COUNTIF(ALUMNOS!E:E,"*"&A25&"*") -> #REF! | M25: 1 | N25: 50 | O25: 4 | P25: 2 | Q25: 0 | R25: 0
A26: ING9003 | B26: INGLES 3 | C26: 2 | D26: =C26*1.5 -> 3 | E26: ING9002 | F26: 6 | H26: =if(IFERROR(VLOOKUP(A26,'Asignaturas2026-2'!B:B,1,False),"")<>"","SI",IF(I26<>"","HOM","")) -> #REF! | I26: =IFERROR(__xludf.DUMMYFUNCTION("if(or(L26=0),"""",IFERROR(TEXTJOIN("", "", TRUE, FILTER( TRIM(SPLIT(G26, "","")), MAP( TRIM(SPLIT(G26, "","")), LAMBDA(clave, COUNTIF('Asignaturas2026-2'!B:B, clave )>0 ) ) ) )))"),"#REF!") -> #REF! | J26: ICD | K26: =COUNTIF(ALUMNOS!D:D,"*"&A26&"*") -> #REF! | L26: =COUNTIF(ALUMNOS!E:E,"*"&A26&"*") -> #REF! | M26: 1 | N26: 25 | O26: 4 | P26: 0 | Q26: 2 | R26: 0
A27: ICD3151 | B27: METODOS NUMERICOS | C27: 3 | D27: =C27*1.5 -> 4.5 | E27: MAT3105 | F27: 6 | G27: ICI3140 | H27: =if(IFERROR(VLOOKUP(A27,'Asignaturas2026-2'!B:B,1,False),"")<>"","SI",IF(I27<>"","HOM","")) -> #REF! | I27: =IFERROR(__xludf.DUMMYFUNCTION("if(or(L27=0),"""",IFERROR(TEXTJOIN("", "", TRUE, FILTER( TRIM(SPLIT(G27, "","")), MAP( TRIM(SPLIT(G27, "","")), LAMBDA(clave, COUNTIF('Asignaturas2026-2'!B:B, clave )>0 ) ) ) )))"),"#REF!") -> #REF! | J27: ICD | K27: =COUNTIF(ALUMNOS!D:D,"*"&A27&"*") -> #REF! | L27: =COUNTIF(ALUMNOS!E:E,"*"&A27&"*") -> #REF! | M27: 1 | N27: 50 | O27: 4 | P27: 0 | Q27: 0 | R27: 0
A28: ICD3152 | B28: ESTADISTICA AVANZADA | C28: 4 | D28: =C28*1.5 -> 6 | E28: ICD3148 | F28: 6 | H28: =if(IFERROR(VLOOKUP(A28,'Asignaturas2026-2'!B:B,1,False),"")<>"","SI",IF(I28<>"","HOM","")) -> #REF! | I28: =IFERROR(__xludf.DUMMYFUNCTION("if(or(L28=0),"""",IFERROR(TEXTJOIN("", "", TRUE, FILTER( TRIM(SPLIT(G28, "","")), MAP( TRIM(SPLIT(G28, "","")), LAMBDA(clave, COUNTIF('Asignaturas2026-2'!B:B, clave )>0 ) ) ) )))"),"#REF!") -> #REF! | J28: ICD | K28: =COUNTIF(ALUMNOS!D:D,"*"&A28&"*") -> #REF! | L28: =COUNTIF(ALUMNOS!E:E,"*"&A28&"*") -> #REF! | M28: 1 | N28: 50 | O28: 4 | P28: 2 | Q28: 0 | R28: 0
A29: ICD3153 | B29: INTELIGENCIA ARTIFICIAL | C29: 4 | D29: =C29*1.5 -> 6 | E29: ICD2347 | F29: 6 | G29: ICI5240,ICI3244 | H29: =if(IFERROR(VLOOKUP(A29,'Asignaturas2026-2'!B:B,1,False),"")<>"","SI",IF(I29<>"","HOM","")) -> #REF! | I29: =IFERROR(__xludf.DUMMYFUNCTION("if(or(L29=0),"""",IFERROR(TEXTJOIN("", "", TRUE, FILTER( TRIM(SPLIT(G29, "","")), MAP( TRIM(SPLIT(G29, "","")), LAMBDA(clave, COUNTIF('Asignaturas2026-2'!B:B, clave )>0 ) ) ) )))"),"#REF!") -> #REF! | J29: ICD | K29: =COUNTIF(ALUMNOS!D:D,"*"&A29&"*") -> #REF! | L29: =COUNTIF(ALUMNOS!E:E,"*"&A29&"*") -> #REF! | M29: 1 | N29: 50 | O29: 4 | P29: 2 | Q29: 0 | R29: 0
A30: ICD3255 | B30: ANALISIS INTELIGENTE DE DATOS | C30: 4 | D30: =C30*1.5 -> 6 | E30: ICD3148 | F30: 6 | H30: =if(IFERROR(VLOOKUP(A30,'Asignaturas2026-2'!B:B,1,False),"")<>"","SI",IF(I30<>"","HOM","")) -> #REF! | I30: =IFERROR(__xludf.DUMMYFUNCTION("if(or(L30=0),"""",IFERROR(TEXTJOIN("", "", TRUE, FILTER( TRIM(SPLIT(G30, "","")), MAP( TRIM(SPLIT(G30, "","")), LAMBDA(clave, COUNTIF('Asignaturas2026-2'!B:B, clave )>0 ) ) ) )))"),"#REF!") -> #REF! | J30: ICD | K30: =COUNTIF(ALUMNOS!D:D,"*"&A30&"*") -> #REF! | L30: =COUNTIF(ALUMNOS!E:E,"*"&A30&"*") -> #REF! | M30: 1 | N30: 50 | O30: 4 | P30: 2 | Q30: 0 | R30: 0
A31: ICD3354 | B31: HARDWARE,SISTEMAS OPERATIVOS | C31: 4 | D31: =C31*1.5 -> 6 | E31: ICD2344 | F31: 6 | G31: INF2322,INF2341,ICI2341,ICI3344 | H31: =if(IFERROR(VLOOKUP(A31,'Asignaturas2026-2'!B:B,1,False),"")<>"","SI",IF(I31<>"","HOM","")) -> #REF! | I31: =IFERROR(__xludf.DUMMYFUNCTION("if(or(L31=0),"""",IFERROR(TEXTJOIN("", "", TRUE, FILTER( TRIM(SPLIT(G31, "","")), MAP( TRIM(SPLIT(G31, "","")), LAMBDA(clave, COUNTIF('Asignaturas2026-2'!B:B, clave )>0 ) ) ) )))"),"#REF!") -> #REF! | J31: ICD | K31: =COUNTIF(ALUMNOS!D:D,"*"&A31&"*") -> #REF! | L31: =COUNTIF(ALUMNOS!E:E,"*"&A31&"*") -> #REF! | M31: 1 | N31: 50 | O31: 4 | P31: 2 | Q31: 0 | R31: 0
A32: ING9004 | B32: INGLES 4 | C32: 2 | D32: =C32*1.5 -> 3 | E32: ING9003 | F32: 7 | H32: =if(IFERROR(VLOOKUP(A32,'Asignaturas2026-2'!B:B,1,False),"")<>"","SI",IF(I32<>"","HOM","")) -> #REF! | I32: =IFERROR(__xludf.DUMMYFUNCTION("if(or(L32=0),"""",IFERROR(TEXTJOIN("", "", TRUE, FILTER( TRIM(SPLIT(G32, "","")), MAP( TRIM(SPLIT(G32, "","")), LAMBDA(clave, COUNTIF('Asignaturas2026-2'!B:B, clave )>0 ) ) ) )))"),"#REF!") -> #REF! | J32: ICD | K32: =COUNTIF(ALUMNOS!D:D,"*"&A32&"*") -> #REF! | L32: =COUNTIF(ALUMNOS!E:E,"*"&A32&"*") -> #REF! | M32: 1 | N32: 25 | O32: 4 | P32: 0 | Q32: 2 | R32: 0
A33: ICA2121 | B33: ADMINISTRACION DE EMPRESAS | C33: 3 | D33: =C33*1.5 -> 4.5 | E33: ICD3149 | F33: 7 | G33: ICA4121,ICA2120 | H33: =if(IFERROR(VLOOKUP(A33,'Asignaturas2026-2'!B:B,1,False),"")<>"","SI",IF(I33<>"","HOM","")) -> #REF! | I33: =IFERROR(__xludf.DUMMYFUNCTION("if(or(L33=0),"""",IFERROR(TEXTJOIN("", "", TRUE, FILTER( TRIM(SPLIT(G33, "","")), MAP( TRIM(SPLIT(G33, "","")), LAMBDA(clave, COUNTIF('Asignaturas2026-2'!B:B, clave )>0 ) ) ) )))"),"#REF!") -> #REF! | J33: ICD | K33: =COUNTIF(ALUMNOS!D:D,"*"&A33&"*") -> #REF! | L33: =COUNTIF(ALUMNOS!E:E,"*"&A33&"*") -> #REF! | M33: 1 | N33: 50 | O33: 4 | P33: 0 | Q33: 0 | R33: 0
A34: ICD4156 | B34: OPTIMIZACION 1 | C34: 4 | D34: =C34*1.5 -> 6 | E34: MAT3105 | F34: 7 | G34: ICI4144,INF3144,ICI4151,INF3136 | H34: =if(IFERROR(VLOOKUP(A34,'Asignaturas2026-2'!B:B,1,False),"")<>"","SI",IF(I34<>"","HOM","")) -> #REF! | I34: =IFERROR(__xludf.DUMMYFUNCTION("if(or(L34=0),"""",IFERROR(TEXTJOIN("", "", TRUE, FILTER( TRIM(SPLIT(G34, "","")), MAP( TRIM(SPLIT(G34, "","")), LAMBDA(clave, COUNTIF('Asignaturas2026-2'!B:B, clave )>0 ) ) ) )))"),"#REF!") -> #REF! | J34: ICD | K34: =COUNTIF(ALUMNOS!D:D,"*"&A34&"*") -> #REF! | L34: =COUNTIF(ALUMNOS!E:E,"*"&A34&"*") -> #REF! | M34: 1 | N34: 50 | O34: 4 | P34: 2 | Q34: 0 | R34: 0
A35: ICD4157 | B35: ANALISIS DE SERIES DE TIEMPO | C35: 4 | D35: =C35*1.5 -> 6 | E35: ICD3152 | F35: 7 | H35: =if(IFERROR(VLOOKUP(A35,'Asignaturas2026-2'!B:B,1,False),"")<>"","SI",IF(I35<>"","HOM","")) -> #REF! | I35: =IFERROR(__xludf.DUMMYFUNCTION("if(or(L35=0),"""",IFERROR(TEXTJOIN("", "", TRUE, FILTER( TRIM(SPLIT(G35, "","")), MAP( TRIM(SPLIT(G35, "","")), LAMBDA(clave, COUNTIF('Asignaturas2026-2'!B:B, clave )>0 ) ) ) )))"),"#REF!") -> #REF! | J35: ICD | K35: =COUNTIF(ALUMNOS!D:D,"*"&A35&"*") -> #REF! | L35: =COUNTIF(ALUMNOS!E:E,"*"&A35&"*") -> #REF! | M35: 1 | N35: 50 | O35: 4 | P35: 2 | Q35: 0 | R35: 0
A36: ICD4258 | B36: APRENDIZAJE AUTOMATICO 1 | C36: 4 | D36: =C36*1.5 -> 6 | E36: ICD3153 | F36: 7 | H36: =if(IFERROR(VLOOKUP(A36,'Asignaturas2026-2'!B:B,1,False),"")<>"","SI",IF(I36<>"","HOM","")) -> #REF! | I36: =IFERROR(__xludf.DUMMYFUNCTION("if(or(L36=0),"""",IFERROR(TEXTJOIN("", "", TRUE, FILTER( TRIM(SPLIT(G36, "","")), MAP( TRIM(SPLIT(G36, "","")), LAMBDA(clave, COUNTIF('Asignaturas2026-2'!B:B, clave )>0 ) ) ) )))"),"#REF!") -> #REF! | J36: ICD | K36: =COUNTIF(ALUMNOS!D:D,"*"&A36&"*") -> #REF! | L36: =COUNTIF(ALUMNOS!E:E,"*"&A36&"*") -> #REF! | M36: 1 | N36: 50 | O36: 4 | P36: 2 | Q36: 0 | R36: 0
A37: ICD4359 | B37: ALMACENAMIENTO,RECUPERACION DE DATOS | C37: 4 | D37: =C37*1.5 -> 6 | E37: ICD3350 | F37: 7 | H37: =if(IFERROR(VLOOKUP(A37,'Asignaturas2026-2'!B:B,1,False),"")<>"","SI",IF(I37<>"","HOM","")) -> #REF! | I37: =IFERROR(__xludf.DUMMYFUNCTION("if(or(L37=0),"""",IFERROR(TEXTJOIN("", "", TRUE, FILTER( TRIM(SPLIT(G37, "","")), MAP( TRIM(SPLIT(G37, "","")), LAMBDA(clave, COUNTIF('Asignaturas2026-2'!B:B, clave )>0 ) ) ) )))"),"#REF!") -> #REF! | J37: ICD | K37: =COUNTIF(ALUMNOS!D:D,"*"&A37&"*") -> #REF! | L37: =COUNTIF(ALUMNOS!E:E,"*"&A37&"*") -> #REF! | M37: 0.92 | N37: 50 | O37: 4 | P37: 2 | Q37: 0 | R37: 0
A38: ICD4160 | B38: OPTIMIZACION 2 | C38: 4 | D38: =C38*1.5 -> 6 | E38: ICD4156 | F38: 8 | G38: ICI5142 | H38: =if(IFERROR(VLOOKUP(A38,'Asignaturas2026-2'!B:B,1,False),"")<>"","SI",IF(I38<>"","HOM","")) -> #REF! | I38: =IFERROR(__xludf.DUMMYFUNCTION("if(or(L38=0),"""",IFERROR(TEXTJOIN("", "", TRUE, FILTER( TRIM(SPLIT(G38, "","")), MAP( TRIM(SPLIT(G38, "","")), LAMBDA(clave, COUNTIF('Asignaturas2026-2'!B:B, clave )>0 ) ) ) )))"),"#REF!") -> #REF! | J38: ICD | K38: =COUNTIF(ALUMNOS!D:D,"*"&A38&"*") -> #REF! | L38: =COUNTIF(ALUMNOS!E:E,"*"&A38&"*") -> #REF! | M38: 1 | N38: 50 | O38: 4 | P38: 2 | Q38: 0 | R38: 0
A39: ICD4262 | B39: APRENDIZAJE AUTOMATICO 2 | C39: 4 | D39: =C39*1.5 -> 6 | E39: ICD4258 | F39: 8 | H39: =if(IFERROR(VLOOKUP(A39,'Asignaturas2026-2'!B:B,1,False),"")<>"","SI",IF(I39<>"","HOM","")) -> #REF! | I39: =IFERROR(__xludf.DUMMYFUNCTION("if(or(L39=0),"""",IFERROR(TEXTJOIN("", "", TRUE, FILTER( TRIM(SPLIT(G39, "","")), MAP( TRIM(SPLIT(G39, "","")), LAMBDA(clave, COUNTIF('Asignaturas2026-2'!B:B, clave )>0 ) ) ) )))"),"#REF!") -> #REF! | J39: ICD | K39: =COUNTIF(ALUMNOS!D:D,"*"&A39&"*") -> #REF! | L39: =COUNTIF(ALUMNOS!E:E,"*"&A39&"*") -> #REF! | M39: 1 | N39: 50 | O39: 4 | P39: 2 | Q39: 0 | R39: 0
A40: ICD4363 | B40: REDES DE COMPUTADORES | C40: 4 | D40: =C40*1.5 -> 6 | E40: ICD3354 | F40: 8 | G40: INF2324,INF3340,ICI3343 | H40: =if(IFERROR(VLOOKUP(A40,'Asignaturas2026-2'!B:B,1,False),"")<>"","SI",IF(I40<>"","HOM","")) -> #REF! | I40: =IFERROR(__xludf.DUMMYFUNCTION("if(or(L40=0),"""",IFERROR(TEXTJOIN("", "", TRUE, FILTER( TRIM(SPLIT(G40, "","")), MAP( TRIM(SPLIT(G40, "","")), LAMBDA(clave, COUNTIF('Asignaturas2026-2'!B:B, clave )>0 ) ) ) )))"),"#REF!") -> #REF! | J40: ICD | K40: =COUNTIF(ALUMNOS!D:D,"*"&A40&"*") -> #REF! | L40: =COUNTIF(ALUMNOS!E:E,"*"&A40&"*") -> #REF! | M40: 1 | N40: 50 | O40: 4 | P40: 2 | Q40: 0 | R40: 0
...

Sheet test.generado-DisponibilidadDoc
A1: Profesor: | B1: DOC001
A2: Bloque | B2: Lunes | C2: Martes | D2: Miércoles | E2: Jueves | F2: Viernes
A3: 1-2
A4: 3-4
A5: 5-6
A6: 7-8
A7: 9-10
A8: 11-12
A9: 13-14
A12: Profesor: | B12: DOC002
A13: Bloque | B13: Lunes | C13: Martes | D13: Miércoles | E13: Jueves | F13: Viernes
A14: 1-2
A15: 3-4
A16: 5-6
A17: 7-8
A18: 9-10
A19: 11-12
A20: 13-14
A23: Profesor: | B23: DOC003
A24: Bloque | B24: Lunes | C24: Martes | D24: Miércoles | E24: Jueves | F24: Viernes
A25: 1-2
A26: 3-4
A27: 5-6
A28: 7-8
A29: 9-10
A30: 11-12
A31: 13-14
A34: Profesor: | B34: DOC004
A35: Bloque | B35: Lunes | C35: Martes | D35: Miércoles | E35: Jueves | F35: Viernes
A36: 1-2
A37: 3-4
A38: 5-6
A39: 7-8
A40: 9-10
A41: 11-12
A42: 13-14
A45: Profesor: | B45: DOC005
A46: Bloque | B46: Lunes | C46: Martes | D46: Miércoles | E46: Jueves | F46: Viernes
A47: 1-2
A48: 3-4
...

Sheet test.generado-HorarioDocente
A1: Profesor: | B1: DOC001
A2: Bloque | B2: Lunes | C2: Martes | D2: Miércoles | E2: Jueves | F2: Viernes
A3: 1-2
A4: 3-4
A5: 5-6 | C5: ASG067 - 01 Lab
A6: 7-8 | D6: ASG001 - 01 Tal
A7: 9-10 | F7: ASG033 - 02 Cát
A8: 11-12 | D8: ASG067 - 01 Cát
A9: 13-14 | C9: ASG033 - 02 Lab
A12: Profesor: | B12: DOC002
A13: Bloque | B13: Lunes | C13: Martes | D13: Miércoles | E13: Jueves | F13: Viernes
A14: 1-2 | D14: ASG034 - 01 Tal
A15: 3-4 | D15: ASG068 - 01 Cát
A16: 5-6 | E16: ASG034 - 01 Cát
A17: 7-8
A18: 9-10 | E18: ASG068 - 01 Lab
A19: 11-12
A20: 13-14 | B20: ASG001 - 02 Tal
A23: Profesor: | B23: DOC003
A24: Bloque | B24: Lunes | C24: Martes | D24: Miércoles | E24: Jueves | F24: Viernes
A25: 1-2
A26: 3-4 | C26: ASG034 - 02 Cát
A27: 5-6
A28: 7-8 | C28: ASG069 - 01 Cát
A29: 9-10 | C29: ASG002 - 01 Cát
A30: 11-12 | D30: ASG069 - 01 Cát
A31: 13-14 | D31: ASG034 - 02 Tal
A34: Profesor: | B34: DOC004
A35: Bloque | B35: Lunes | C35: Martes | D35: Miércoles | E35: Jueves | F35: Viernes
A36: 1-2
A37: 3-4
A38: 5-6
A39: 7-8
A40: 9-10 | B40: ASG002 - 02 Cát | F40: ASG070 - 01 Lab
A41: 11-12 | B41: ASG035 - 01 Cát
A42: 13-14 | C42: ASG070 - 01 Cát
A45: Profesor: | B45: DOC005
A46: Bloque | B46: Lunes | C46: Martes | D46: Miércoles | E46: Jueves | F46: Viernes
A47: 1-2
A48: 3-4 | B48: ASG003 - 01 Cát
...

Sheet test.generado-HorarioMaestro
A1: Día | B1: Bloque | C1: Curso | D1: Actividad | E1: Profesores | F1: Sala | G1: Estudiantes | H1: Curso | I1: Actividad | J1: Profesores | K1: Sala | L1: Estudiantes | M1: Curso | N1: Actividad | O1: Profesores | P1: Sala | Q1: Estudiantes | R1: Curso | S1: Actividad | T1: Profesores | U1: Sala | V1: Estudiantes | W1: Curso | X1: Actividad | Y1: Profesores | Z1: Sala | AA1: Estudiantes | AB1: Curso | AC1: Actividad | AD1: Profesores | AE1: Sala | AF1: Estudiantes | AG1: Curso | AH1: Actividad | AI1: Profesores | AJ1: Sala | AK1: Estudiantes | AL1: Curso | AM1: Actividad | AN1: Profesores | AO1: Sala | AP1: Estudiantes | AQ1: Curso | AR1: Actividad | AS1: Profesores | AT1: Sala | AU1: Estudiantes | AV1: Curso | AW1: Actividad | AX1: Profesores | AY1: Sala | AZ1: Estudiantes | BA1: Curso | BB1: Actividad | BC1: Profesores | BD1: Sala | BE1: Estudiantes | BF1: Curso | BG1: Actividad | BH1: Profesores | BI1: Sala | BJ1: Estudiantes
A2: Lu | B2: 1-2 | C2: ASG020-01 | D2: Cát | E2: DOC029 | H2: ASG031-01 | I2: Ay. | M2: ASG039-02 | N2: Cát | O2: DOC010 | R2: ASG055-01 | S2: Cát | T2: DOC033 | W2: ASG062-01 | X2: Cát | Y2: DOC044
A3: Lu | B3: 3-4 | C3: ASG003-01 | D3: Cát | E3: DOC005 | H3: ASG022-02 | I3: Cát | J3: DOC033 | M3: ASG024-01 | N3: Ay. | R3: ASG040-01 | S3: Ay. | W3: ASG045-01 | X3: Lab | Y3: DOC019 | AB3: ASG064-01 | AC3: Cát | AD3: DOC047
A4: Lu | B4: 5-6 | C4: ASG037-01 | D4: Cát | E4: DOC006 | H4: ASG043-01 | I4: Lab | J4: DOC016 | M4: ASG044-01 | N4: Cát | O4: DOC018 | R4: ASG047-02 | S4: Cát | T4: DOC023 | W4: ASG052-01 | X4: Lab | Y4: DOC030 | AB4: ASG066-01 | AC4: Ay.
A5: Lu | B5: 7-8 | C5: ASG002-02 | D5: Lab | E5: DOC010 | H5: ASG006-02 | I5: Lab | J5: DOC009 | M5: ASG012-02 | N5: Cát | O5: DOC019 | R5: ASG018-01 | S5: Cát | T5: DOC026 | W5: ASG027-01 | X5: Cát | Y5: DOC041 | AB5: ASG046-01 | AC5: Lab | AD5: DOC021 | AG5: ASG050-01 | AH5: Ay.
A6: Lu | B6: 9-10 | C6: ASG002-02 | D6: Cát | E6: DOC004 | H6: ASG004-01 | I6: Cát | J6: DOC006 | M6: ASG008-02 | N6: Cát | O6: DOC013 | R6: ASG011-01 | S6: Tal | T6: DOC016 | W6: ASG012-01 | X6: Tal | Y6: DOC018 | AB6: ASG013-02 | AC6: Tal | AD6: DOC021 | AG6: ASG017-01 | AH6: Tal | AI6: DOC025 | AL6: ASG027-02 | AM6: Tal | AN6: DOC042 | AQ6: ASG028-01 | AR6: Cát | AS6: DOC043 | AV6: ASG030-01 | AW6: Lab | AX6: DOC046 | BA6: ASG036-01 | BB6: Cát | BC6: DOC005 | BF6: ASG063-01 | BG6: Tal | BH6: DOC045
A7: Lu | B7: 11-12 | C7: ASG013-01 | D7: Cát | E7: DOC020 | H7: ASG029-01 | I7: Lab | J7: DOC045 | M7: ASG035-01 | N7: Cát | O7: DOC004 | R7: ASG039-01 | S7: Cát | T7: DOC009 | W7: ASG042-01 | X7: Cát | Y7: DOC015 | AB7: ASG048-02 | AC7: Cát | AD7: DOC025 | AG7: ASG054-01 | AH7: Tal | AI7: DOC032 | AL7: ASG055-02 | AM7: Cát | AN7: DOC034
A8: Lu | B8: 13-14 | C8: ASG001-02 | D8: Tal | E8: DOC002 | H8: ASG009-01 | I8: Cát | J8: DOC014 | M8: ASG010-01 | N8: Cát | O8: DOC015 | R8: ASG024-02 | S8: Cát | T8: DOC037 | W8: ASG026-01 | X8: Cát | Y8: DOC040 | AB8: ASG047-01 | AC8: Ay.
A9: Ma | B9: 1-2 | C9: ASG006-01 | D9: Lab | E9: DOC008 | H9: ASG012-02 | I9: Cát | J9: DOC019 | M9: ASG030-01 | N9: Cát | O9: DOC046 | R9: ASG055-01 | S9: Lab | T9: DOC033 | W9: ASG055-02 | X9: Lab | Y9: DOC034
A10: Ma | B10: 3-4 | C10: ASG019-01 | D10: Cát | E10: DOC027 | H10: ASG019-02 | I10: Cát | J10: DOC028 | M10: ASG031-02 | N10: Lab | O10: DOC048 | R10: ASG034-02 | S10: Cát | T10: DOC003 | W10: ASG040-02 | X10: Lab | Y10: DOC012 | AB10: ASG041-02 | AC10: Tal | AD10: DOC014 | AG10: ASG056-01 | AH10: Lab | AI10: DOC035 | AL10: ASG058-01 | AM10: Cát | AN10: DOC038 | AQ10: ASG059-02 | AR10: Lab | AS10: DOC041 | AV10: ASG063-02 | AW10: Cát | AX10: DOC046
A11: Ma | B11: 5-6 | C11: ASG005-01 | D11: Cát | E11: DOC007 | H11: ASG012-01 | I11: Cát | J11: DOC018 | M11: ASG022-02 | N11: Cát | O11: DOC033 | R11: ASG031-01 | S11: Lab | T11: DOC047 | W11: ASG058-02 | X11: Cát | Y11: DOC039 | AB11: ASG067-01 | AC11: Lab | AD11: DOC001
A12: Ma | B12: 7-8 | C12: ASG022-01 | D12: Cát | E12: DOC032 | H12: ASG029-01 | I12: Cát | J12: DOC045 | M12: ASG043-02 | N12: Lab | O12: DOC017 | R12: ASG044-01 | S12: Cát | T12: DOC018 | W12: ASG046-01 | X12: Tal | Y12: DOC021 | AB12: ASG048-01 | AC12: Cát | AD12: DOC024 | AG12: ASG050-01 | AH12: Cát | AI12: DOC027 | AL12: ASG059-01 | AM12: Lab | AN12: DOC040 | AQ12: ASG069-01 | AR12: Cát | AS12: DOC003
A13: Ma | B13: 9-10 | C13: ASG002-01 | D13: Cát | E13: DOC003 | H13: ASG011-02 | I13: Lab | J13: DOC017 | M13: ASG013-02 | N13: Cát | O13: DOC021 | R13: ASG020-02 | S13: Lab | T13: DOC030 | W13: ASG021-01 | X13: Tal | Y13: DOC031 | AB13: ASG025-01 | AC13: Tal | AD13: DOC038 | AG13: ASG026-01 | AH13: Lab | AI13: DOC040 | AL13: ASG027-01 | AM13: Tal | AN13: DOC041 | AQ13: ASG028-01 | AR13: Cát | AS13: DOC043 | AV13: ASG031-02 | AW13: Ay. | BA13: ASG038-02 | BB13: Cát | BC13: DOC008 | BF13: ASG057-02 | BG13: Lab | BH13: DOC037
A14: Ma | B14: 11-12 | C14: ASG023-01 | D14: Tal | E14: DOC034 | H14: ASG025-02 | I14: Tal | J14: DOC039 | M14: ASG038-01 | N14: Cát | O14: DOC007 | R14: ASG042-01 | S14: Ay. | W14: ASG051-01 | X14: Lab | Y14: DOC028 | AB14: ASG052-01 | AC14: Cát | AD14: DOC030
A15: Ma | B15: 13-14 | C15: ASG008-01 | D15: Cát | E15: DOC012 | H15: ASG033-02 | I15: Lab | J15: DOC001 | M15: ASG042-01 | N15: Tal | O15: DOC015 | R15: ASG047-02 | S15: Cát | T15: DOC023 | W15: ASG064-02 | X15: Cát | Y15: DOC048 | AB15: ASG065-01 | AC15: Cát | AD15: DOC049 | AG15: ASG070-01 | AH15: Cát | AI15: DOC004
A16: Mi | B16: 1-2 | C16: ASG008-02 | D16: Ay. | H16: ASG029-01 | I16: Lab | J16: DOC045 | M16: ASG032-01 | N16: Cát | O16: DOC049 | R16: ASG034-01 | S16: Tal | T16: DOC002
A17: Mi | B17: 3-4 | C17: ASG025-02 | D17: Cát | E17: DOC039 | H17: ASG028-02 | I17: Cát | J17: DOC044 | M17: ASG031-01 | N17: Cát | O17: DOC047 | R17: ASG035-01 | S17: Ay. | W17: ASG040-01 | X17: Lab | Y17: DOC011 | AB17: ASG041-02 | AC17: Cát | AD17: DOC014 | AG17: ASG052-01 | AH17: Cát | AI17: DOC030 | AL17: ASG064-01 | AM17: Ay. | AQ17: ASG068-01 | AR17: Cát | AS17: DOC002
A18: Mi | B18: 5-6 | C18: ASG007-02 | D18: Lab | E18: DOC011 | H18: ASG011-01 | I18: Lab | J18: DOC016 | M18: ASG016-01 | N18: Ay. | R18: ASG019-02 | S18: Tal | T18: DOC028 | W18: ASG028-02 | X18: Cát | Y18: DOC044 | AB18: ASG033-01 | AC18: Lab | AD18: DOC050 | AG18: ASG041-01 | AH18: Tal | AI18: DOC013 | AL18: ASG048-02 | AM18: Ay. | AQ18: ASG053-01 | AR18: Cát | AS18: DOC031 | AV18: ASG058-02 | AW18: Cát | AX18: DOC039 | BA18: ASG063-01 | BB18: Ay.
A19: Mi | B19: 7-8 | C19: ASG001-01 | D19: Tal | E19: DOC001 | H19: ASG003-01 | I19: Lab | J19: DOC011 | M19: ASG009-01 | N19: Tal | O19: DOC014 | R19: ASG010-01 | S19: Cát | T19: DOC015 | W19: ASG023-01 | X19: Ay. | AB19: ASG038-01 | AC19: Cát | AD19: DOC007 | AG19: ASG043-01 | AH19: Lab | AI19: DOC016 | AL19: ASG056-01 | AM19: Lab | AN19: DOC035 | AQ19: ASG057-01 | AR19: Lab | AS19: DOC036 | AV19: ASG063-02 | AW19: Ay. | BA19: ASG066-01 | BB19: Cát | BC19: DOC050
A20: Mi | B20: 9-10 | C20: ASG012-02 | D20: Tal | E20: DOC019 | H20: ASG018-01 | I20: Ay. | M20: ASG020-02 | N20: Cát | O20: DOC030 | R20: ASG039-01 | S20: Cát | T20: DOC009 | W20: ASG044-01 | X20: Cát | Y20: DOC018 | AB20: ASG047-02 | AC20: Ay. | AG20: ASG063-01 | AH20: Cát | AI20: DOC045
A21: Mi | B21: 11-12 | C21: ASG014-01 | D21: Lab | E21: DOC022 | H21: ASG046-01 | I21: Cát | J21: DOC021 | M21: ASG060-01 | N21: Ay. | R21: ASG067-01 | S21: Cát | T21: DOC001 | W21: ASG069-01 | X21: Cát | Y21: DOC003
A22: Mi | B22: 13-14 | C22: ASG006-02 | D22: Lab | E22: DOC009 | H22: ASG012-01 | I22: Cát | J22: DOC018 | M22: ASG017-01 | N22: Cát | O22: DOC025 | R22: ASG034-02 | S22: Tal | T22: DOC003 | W22: ASG037-01 | X22: Cát | Y22: DOC006 | AB22: ASG045-01 | AC22: Cát | AD22: DOC019
A23: Ju | B23: 1-2 | C23: ASG001-02 | D23: Cát | E23: DOC008 | H23: ASG014-01 | I23: Cát | J23: DOC022 | M23: ASG023-02 | N23: Ay. | R23: ASG040-02 | S23: Ay. | W23: ASG055-01 | X23: Cát | Y23: DOC033 | AB23: ASG060-01 | AC23: Cát | AD23: DOC042
A24: Ju | B24: 3-4 | C24: ASG006-01 | D24: Lab | E24: DOC008 | H24: ASG015-01 | I24: Cát | J24: DOC023 | M24: ASG020-01 | N24: Lab | O24: DOC029 | R24: ASG025-01 | S24: Cát | T24: DOC038 | W24: ASG030-01 | X24: Cát | Y24: DOC046 | AB24: ASG061-01 | AC24: Ay.
A25: Ju | B25: 5-6 | C25: ASG008-01 | D25: Ay. | H25: ASG019-02 | I25: Cát | J25: DOC028 | M25: ASG024-02 | N25: Ay. | R25: ASG025-02 | S25: Cát | T25: DOC039 | W25: ASG034-01 | X25: Cát | Y25: DOC002 | AB25: ASG048-02 | AC25: Cát | AD25: DOC025
A26: Ju | B26: 7-8
A27: Ju | B27: 9-10 | C27: ASG011-02 | D27: Tal | E27: DOC017 | H27: ASG027-02 | I27: Cát | J27: DOC042 | M27: ASG028-02 | N27: Cát | O27: DOC044 | R27: ASG045-02 | S27: Cát | T27: DOC020 | W27: ASG051-01 | X27: Cát | Y27: DOC028 | AB27: ASG051-02 | AC27: Lab | AD27: DOC029 | AG27: ASG057-02 | AH27: Cát | AI27: DOC037 | AL27: ASG058-01 | AM27: Cát | AN27: DOC038 | AQ27: ASG063-02 | AR27: Tal | AS27: DOC046 | AV27: ASG068-01 | AW27: Lab | AX27: DOC002
A28: Ju | B28: 11-12 | C28: ASG007-01 | D28: Lab | E28: DOC010 | H28: ASG015-01 | I28: Cát | J28: DOC023 | M28: ASG043-01 | N28: Tal | O28: DOC016 | R28: ASG043-02 | S28: Lab | T28: DOC017 | W28: ASG047-01 | X28: Cát | Y28: DOC022 | AB28: ASG055-02 | AC28: Cát | AD28: DOC034 | AG28: ASG059-01 | AH28: Lab | AI28: DOC040 | AL28: ASG064-02 | AM28: Ay.
A29: Ju | B29: 13-14 | C29: ASG015-01 | D29: Cát | E29: DOC023 | H29: ASG019-01 | I29: Tal | J29: DOC027 | M29: ASG026-01 | N29: Cát | O29: DOC040 | R29: ASG031-02 | S29: Cát | T29: DOC048 | W29: ASG048-01 | X29: Ay. | AB29: ASG062-01 | AC29: Lab | AD29: DOC044
A30: Vi | B30: 1-2 | C30: ASG005-01 | D30: Cát | E30: DOC007 | H30: ASG022-01 | I30: Cát | J30: DOC032 | M30: ASG023-02 | N30: Tal | O30: DOC035 | R30: ASG025-01 | S30: Cát | T30: DOC038 | W30: ASG041-01 | X30: Cát | Y30: DOC013 | AB30: ASG043-02 | AC30: Tal | AD30: DOC017 | AG30: ASG045-02 | AH30: Lab | AI30: DOC020
A31: Vi | B31: 3-4 | C31: ASG021-01 | D31: Ay. | H31: ASG049-01 | I31: Ay. | M31: ASG061-01 | N31: Cát | O31: DOC043 | R31: ASG065-01 | S31: Cát | T31: DOC049
A32: Vi | B32: 5-6 | C32: ASG027-02 | D32: Tal | E32: DOC042 | H32: ASG028-01 | I32: Cát | J32: DOC043 | M32: ASG049-01 | N32: Cát | O32: DOC026 | R32: ASG053-01 | S32: Lab | T32: DOC031 | W32: ASG059-02 | X32: Lab | Y32: DOC041 | AB32: ASG066-01 | AC32: Cát | AD32: DOC050
A33: Vi | B33: 7-8 | C33: ASG007-02 | D33: Lab | E33: DOC011 | H33: ASG016-01 | I33: Cát | J33: DOC024 | M33: ASG027-01 | N33: Tal | O33: DOC041 | R33: ASG036-01 | S33: Cát | T33: DOC005 | W33: ASG038-02 | X33: Cát | Y33: DOC008
A34: Vi | B34: 9-10 | C34: ASG001-01 | D34: Cát | E34: DOC005 | H34: ASG002-01 | I34: Lab | J34: DOC009 | M34: ASG013-01 | N34: Tal | O34: DOC020 | R34: ASG019-01 | S34: Cát | T34: DOC027 | W34: ASG033-02 | X34: Cát | Y34: DOC001 | AB34: ASG057-01 | AC34: Cát | AD34: DOC036 | AG34: ASG070-01 | AH34: Lab | AI34: DOC004
A35: Vi | B35: 11-12 | C35: ASG004-01 | D35: Ay. | H35: ASG007-01 | I35: Lab | J35: DOC010 | M35: ASG024-01 | N35: Cát | O35: DOC036 | R35: ASG032-01 | S35: Lab | T35: DOC049 | W35: ASG033-01 | X35: Cát | Y35: DOC050 | AB35: ASG051-02 | AC35: Cát | AD35: DOC029 | AG35: ASG054-01 | AH35: Cát | AI35: DOC032
A36: Vi | B36: 13-14 | C36: ASG003-01 | D36: Lab | E36: DOC005 | H36: ASG039-02 | I36: Cát | J36: DOC010 | M36: ASG047-01 | N36: Cát | O36: DOC022 | R36: ASG048-01 | S36: Cát | T36: DOC024

Sheet test.generado-Asignaturas
A1: Código | B1: Carrera | C1: Semestre | D1: Nombre | E1: Profesores | F1: Horario
A2: ASG001-01 | B2: CUR01 | C2: 01 | D2: Asignatura ASG001 | E2: DOC001, DOC005, DOC006, DOC007 | F2: Mi 7-8 Tal, Vi 9-10 Cát
A3: ASG001-02 | B3: CUR01 | C3: 01 | D3: Asignatura ASG001 | E3: DOC002, DOC008, DOC012, DOC013 | F3: Lu 13-14 Tal, Ju 1-2 Cát
A4: ASG002-01 | B4: CUR07 | C4: 01 | D4: Asignatura ASG002 | E4: DOC003, DOC009, DOC014 | F4: Ma 9-10 Cát, Vi 9-10 Lab
A5: ASG002-02 | B5: CUR07 | C5: 01 | D5: Asignatura ASG002 | E5: DOC004, DOC010 | F5: Lu 9-10 Cát, Lu 7-8 Lab
A6: ASG003-01 | B6: CUR13 | C6: 01 | D6: Asignatura ASG003 | E6: DOC005, DOC011 | F6: Vi 13-14 Lab, Mi 7-8 Lab, Lu 3-4 Cát
A7: ASG004-01 | B7: CUR01 | C7: 01 | D7: Asignatura ASG004 | E7: DOC006, DOC015 | F7: Lu 9-10 Cát, Vi 11-12 Ay.
A8: ASG005-01 | B8: CUR03 | C8: 01 | D8: Asignatura ASG005 | E8: DOC007 | F8: Vi 1-2 Cát, Ma 5-6 Cát
A9: ASG006-01 | B9: CUR02 | C9: 01 | D9: Asignatura ASG006 | E9: DOC008 | F9: Ju 3-4 Lab, Ma 1-2 Lab
A10: ASG006-02 | B10: CUR02 | C10: 01 | D10: Asignatura ASG006 | E10: DOC009 | F10: Mi 13-14 Lab, Lu 7-8 Lab
A11: ASG007-01 | B11: CUR08 | C11: 01 | D11: Asignatura ASG007 | E11: DOC010 | F11: Ju 11-12 Lab, Vi 11-12 Lab
A12: ASG007-02 | B12: CUR08 | C12: 01 | D12: Asignatura ASG007 | E12: DOC011 | F12: Mi 5-6 Lab, Vi 7-8 Lab
... A105: ASG070-01 | B105: CUR14 | C105: 01 | D105: Asignatura ASG070 | E105: DOC004 | F105: Vi 9-10 Lab, Ma 13-14 Cát

Sheet test.generado-Profesores
A1: Nombre | B1: Asignaturas
A2: DOC001 | B2: ASG001-01, ASG033-02, ASG067-01
A3: DOC002 | B3: ASG001-02, ASG034-01, ASG068-01
A4: DOC003 | B4: ASG002-01, ASG034-02, ASG069-01
A5: DOC004 | B5: ASG002-02, ASG035-01, ASG070-01
A6: DOC005 | B6: ASG001-01, ASG003-01, ASG036-01
A7: DOC006 | B7: ASG001-01, ASG004-01, ASG037-01
A8: DOC007 | B8: ASG001-01, ASG005-01, ASG038-01
A9: DOC008 | B9: ASG001-02, ASG006-01, ASG038-02
A10: DOC009 | B10: ASG002-01, ASG006-02, ASG039-01
A11: DOC010 | B11: ASG002-02, ASG007-01, ASG039-02
A12: DOC011 | B12: ASG003-01, ASG007-02, ASG040-01
... A51: DOC050 | B51: ASG033-01, ASG066-01

Sheet test.generado-Alumnos
A1: ID | B1: Asignaturas
A2: EST0001 | B2: ASG039-01, ASG057-01, ASG059-01
A3: EST0002 | B3: ASG029-01, ASG031-02, ASG064-02
A4: EST0003 | B4: ASG005-01, ASG024-01, ASG033-02, ASG055-01
A5: EST0004 | B5: ASG005-01, ASG024-01, ASG066-01
A6: EST0005 | B6: ASG013-02, ASG018-01, ASG048-01
A7: EST0006 | B7: ASG001-01, ASG004-01, ASG052-01
A8: EST0007 | B8: ASG007-02, ASG044-01, ASG049-01
A9: EST0008 | B9: ASG003-01, ASG026-01, ASG046-01
A10: EST0009 | B10: ASG007-02, ASG044-01, ASG049-01
A11: EST0010 | B11: ASG008-01, ASG028-01, ASG059-01, ASG061-01
A12: EST0011 | B12: ASG002-02, ASG043-02, ASG056-01
... A1201: EST1200 | B1201: ASG015-01, ASG036-01, ASG041-02

Sheet Evaluación de FO
A1: Panel Detalle (optimizada con búsqueda local) | H1: Parámetros para Ejecutar Evaluación
A2: Fecha | B2: 46171.727 | C2: FO | D2: 3.7534858 | E2: Choques | F2: 83
A3: Ratio Desbalance | B3: 0.72103662 | C3: Ratio Ventana | D3: 5.2056799 | H3: ALFA | I3: 1
A4: Estudiantes con carga | B4: 1162 | C4: Ventanas (raw) total | D4: 5395 | E4: Choques (dup) total | F4: 83 | H4: CV IDEAL | I4: 0.1
H5: VENTANA IDEAL | I5: 4
A6: Distribución Ventanas | B6: Estudiantes con esas ventanas | C6: Estudiantes (<=raw) | D6: % Estudiantes (<=raw) | E6: Distribución Choques (duplicados) | F6: Estudiantes | G6: %
A7: 0 | B7: 181 | C7: 181 | D7: 15.6% | E7: 0 | F7: 1093 | G7: 94.1% | H7: HOJA MALLA | I7: MALLAS
A8: 1 | B8: 66 | C8: 247 | D8: 21.3% | E8: 1 | F8: 56 | G8: 4.8% | H8: HOJA HORARIOS | I8: Semestre 2025-1.generado-HorarioMaestro
A9: 2 | B9: 156 | C9: 403 | D9: 34.7% | E9: 2 | F9: 12 | G9: 0.01 | H9: HOJA MATRÍCULAS | I9: Semestre 2025-1.generado-Alumnos
A10: 3 | B10: 93 | C10: 496 | D10: 42.7% | E10: 3 | F10: 1 | G10: 0.1% | H10: RESOLVER SEGMENTACIÓN DE ESTUDIANTES | I10: 0
A11: 4 | B11: 60 | C11: 556 | D11: 47.8%
A12: 5 | B12: 235 | C12: 791 | D12: 68.1% | H12: Guía para leer el “Panel Detalle (última ejecución)”
A13: 6 | B13: 37 | C13: 828 | D13: 71.3%
A14: 7 | B14: 54 | C14: 882 | D14: 75.9%
A15: 8 | B15: 95 | C15: 977 | D15: 84.1%
A16: 9 | B16: 44 | C16: 1021 | D16: 87.9%
A17: 10 | B17: 46 | C17: 1067 | D17: 91.8%
A18: 11 | B18: 64 | C18: 1131 | D18: 97.3%
A19: 12 | B19: 18 | C19: 1149 | D19: 98.9%
A20: 13 | B20: 1 | C20: 1150 | D20: 0.99
A21: 14 | B21: 7 | C21: 1157 | D21: 99.6%
A22: 15 | B22: 4 | C22: 1161 | D22: 99.9%
A23: 16 | B23: 1 | C23: 1162 | D23: 1
A25: Matrícula por asignatura | B25: Alumnos | C25: % | E25: Matrícula por paralelo | F25: Alumnos | G25: %
A26: ICI2145 | B26: 168 | C26: 14.5% | E26: ICI4247-01 | F26: 85 | G26: 7.3%
A27: ICI1241 | B27: 154 | C27: 13.3% | E27: ICI4344-01 | F27: 65 | G27: 5.6%
A28: ICI1458 | B28: 150 | C28: 12.9% | E28: INF2121-01 | F28: 64 | G28: 5.5%
A29: ICI1243 | B29: 147 | C29: 12.7% | E29: INF2121-02 | F29: 63 | G29: 5.4%
A30: ICI3244 | B30: 141 | C30: 12.1% | E30: ICI2145-02 | F30: 61 | G30: 5.2%
A31: ICI3245 | B31: 138 | C31: 11.9% | E31: ICI4150-01 | F31: 59 | G31: 5.1%
A32: INF1211 | B32: 132 | C32: 11.4% | E32: ICI3344-01 | F32: 58 | G32: 0.05
A33: ICI3240 | B33: 127 | C33: 10.9% | E33: ICI3344-02 | F33: 58 | G33: 0.05
A34: INF2121 | B34: 127 | C34: 10.9% | E34: ICI6442-02 | F34: 58 | G34: 0.05
A35: INF1212 | B35: 123 | C35: 10.6% | E35: INF3234-01 | F35: 56 | G35: 4.8%
A36: INF1413 | B36: 122 | C36: 10.5% | E36: INF4552-01 | F36: 56 | G36: 4.8%
A37: ICI3344 | B37: 116 | C37: 0.1 | E37: ICI2145-01 | F37: 55 | G37: 4.7%
A38: ICI2240 | B38: 98 | C38: 8.4% | E38: ICI5475-01 | F38: 54 | G38: 4.6%
A39: INF2322 | B39: 98 | C39: 8.4% | E39: ICI6441-01 | F39: 54 | G39: 4.6%
A40: ICI4244 | B40: 90 | C40: 7.7% | E40: ICI1458-01 | F40: 53 | G40: 4.6%
A41: ICI4151 | B41: 86 | C41: 7.4% | E41: ICI1458-03 | F41: 53 | G41: 4.6%
...
